Workbook

Sheet HCO_Data
A1: HCO Class | C1: HCO Information | I1: HCO Details | S1: HCO Claims | W1: Clinical Trials | AC1: Associations
C2: HCO Comments | D2: Expert Centre | E2: Pancreatic (Cancer) Center | F2: HCP count | G2: Testing check | H2: Referral check | I2: Finessgeo | J2: VeevaID | K2: GDS_HCO_ID | L2: HCO name | M2: Address | N2: Zipcode | O2: City | P2: Region | Q2: Country | S2: C25 | T2: C25 Helper Column | U2: CCAM HNFA0070 | V2: 80% hospital | W2: Unique Clinical Trials | X2: PDAC OR Pancreatic Adenocarcinoma | Y2: KRAS mutation | Z2: Pancreatic cancer | AA2: Unresectable | AB2: Metastatic | AC2: BACAP | AD2: Unicancer Network | AE2: OECI Member | AF2: INCa : Chemotherapy or other cancer specific medical treatments | AG2: INCa : Cancer Surgery: digestive
A3: filter | C3: filter | D3: filter | E3: filter | J3: filter | K3: filter | L3: filter | M3: filter | N3: filter | O3: filter | P3: filter | Q3: filter | R3: Number | S3: filter | U3: filter | W3: filter | X3: filter | Y3: filter | Z3: filter | AA3: filter | AB3: filter | AC3: filter | AD3: filter | AE3: filter | AF3: filter | AG3: filter
B4: 49 | C4: IPC provides multidisciplinary pancreatic cancer care including surgery, systemic therapy and pancreatic-specific research. | D4: Unicancer | F4: =COUNTIF(HCPs!W:W,HCO_Data!K4) -> 25 | G4: =IF(COUNTIF('Testing Referrals'!B:B,HCO_Data!K4)>0,"Yes","") -> Yes | H4: =COUNTIF('HCO referrals'!B:B,HCO_Data!K4)+COUNTIF('HCO referrals'!C:C,HCO_Data!K4) -> 0 | I4: 130001647 | K4: ID00011 | L4: Institut Paoli-Calmettes | M4: 232 Boulevard de Sainte-Marguerite | N4: 13009 | O4: Marseille | P4: Provence-Alpes-Côte d’Azur | Q4: France | R4: 2 | S4: 539 | T4: 539 | V4: Yes | W4: =COUNTIFS('Clinical Trials HCO'!$A:$A, K4, 'Clinical Trials HCO'!$D:$D, "<>") -> 60 | AE4: Certified Comprehensive Cancer Centre
B5: 273 | C5: Beaujon has site-level evidence for pancreatic oncology/pancreatology, pancreatic surgery, EUS/CPRE and rapid pancreatic diagnosis. These activities are organised across dedicated pancreatic, HPB surgical and digestive endoscopy services. | F5: =COUNTIF(HCPs!W:W,HCO_Data!K5) -> 18 | G5: =IF(COUNTIF('Testing Referrals'!B:B,HCO_Data!K5)>0,"Yes","") -> Yes | H5: =COUNTIF('HCO referrals'!B:B,HCO_Data!K5)+COUNTIF('HCO referrals'!C:C,HCO_Data!K5) -> 1 | I5: 920100039 | K5: ID00001 | L5: Hôpital Beaujon | M5: 100 BOULEVARD DU GÉNÉRAL LECLERC | N5: 92118 | O5: CLICHY | Q5: France | R5: 1 | S5: 537 | T5: 537 | V5: Yes | W5: =COUNTIFS('Clinical Trials HCO'!$A:$A, K5, 'Clinical Trials HCO'!$D:$D, "<>") -> 50 | AE5: Certified Comprehensive Cancer Centre
B6: 661 | F6: =COUNTIF(HCPs!W:W,HCO_Data!K6) -> 4 | G6: =IF(COUNTIF('Testing Referrals'!B:B,HCO_Data!K6)>0,"Yes","") -> Yes | H6: =COUNTIF('HCO referrals'!B:B,HCO_Data!K6)+COUNTIF('HCO referrals'!C:C,HCO_Data!K6) -> 0 | I6: 330783648 | K6: ID00031 | L6: Hôpital Haut-Lévêque | M6: AVENUE DE MAGELLAN | N6: 33604 | O6: PESSAC | Q6: France | R6: 3 | S6: 493 | T6: 493 | V6: Yes | W6: =COUNTIFS('Clinical Trials HCO'!$A:$A, K6, 'Clinical Trials HCO'!$D:$D, "<>") -> 23 | AC6: Yes | AG6: Yes
B7: 572 | C7: Jean Mermoz is a genuine comprehensive pancreatic centre rather than merely a diagnostic or surgical provider. Diagnosis/EUS-biopsy, advanced biliopancreatic endoscopy, pancreatic oncology, pancreatic research and high-volume pancreatic surgery are all documented locally. | F7: =COUNTIF(HCPs!W:W,HCO_Data!K7) -> 13 | G7: =IF(COUNTIF('Testing Referrals'!B:B,HCO_Data!K7)>0,"Yes","") | H7: =COUNTIF('HCO referrals'!B:B,HCO_Data!K7)+COUNTIF('HCO referrals'!C:C,HCO_Data!K7) -> 0 | I7: 690023411 | K7: ID00015 | L7: Hôpital Privé Jean Mermoz | M7: 55 AVENUE JEAN MERMOZ | N7: 69008 | O7: LYON | Q7: France | R7: 6 | S7: 384 | T7: 384 | V7: Yes | W7: =COUNTIFS('Clinical Trials HCO'!$A:$A, K7, 'Clinical Trials HCO'!$D:$D, "<>") -> 25 | AC7: Yes | AG7: Yes
B8: 46 | C8: Gustave Roussy provides pancreatic cancer diagnosis, systemic therapy, oncological surgery, EUS and weekly multidisciplinary review at Villejuif. The InstaDiag Pancreas pathway directly integrates radiology, oncology and surgery. | D8: Unicancer | F8: =COUNTIF(HCPs!W:W,HCO_Data!K8) -> 13 | G8: =IF(COUNTIF('Testing Referrals'!B:B,HCO_Data!K8)>0,"Yes","") -> Yes | H8: =COUNTIF('HCO referrals'!B:B,HCO_Data!K8)+COUNTIF('HCO referrals'!C:C,HCO_Data!K8) -> 3 | I8: 940000664 | K8: ID00007 | L8: Institut Gustave Roussy | M8: 114 Rue Edouard Vaillant | N8: 94805 | O8: Villejuif | P8: Ile-de-France | Q8: France | R8: 0 | S8: 364 | T8: 364 | V8: Yes | W8: =COUNTIFS('Clinical Trials HCO'!$A:$A, K8, 'Clinical Trials HCO'!$D:$D, "<>") -> 92 | AF8: Yes | AG8: Yes
B9: 282 | C9: The leading center for the treatment of pancreatic cancer in Montpellier | D9: Unicancer | F9: =COUNTIF(HCPs!W:W,HCO_Data!K9) -> 12 | G9: =IF(COUNTIF('Testing Referrals'!B:B,HCO_Data!K9)>0,"Yes","") -> Yes | H9: =COUNTIF('HCO referrals'!B:B,HCO_Data!K9)+COUNTIF('HCO referrals'!C:C,HCO_Data!K9) -> 2 | I9: 340000207 | K9: ID00026 | L9: ICM Montpellier | M9: 208 RUE DES APOTHICAIRES | N9: 34298 | O9: MONTPELLIER | Q9: France | R9: 5 | S9: 309 | T9: 309 | V9: Yes | W9: =COUNTIFS('Clinical Trials HCO'!$A:$A, K9, 'Clinical Trials HCO'!$D:$D, "<>") -> 42 | AC9: Yes
B10: 243 | F10: =COUNTIF(HCPs!W:W,HCO_Data!K10) -> 14 | G10: =IF(COUNTIF('Testing Referrals'!B:B,HCO_Data!K10)>0,"Yes","") | H10: =COUNTIF('HCO referrals'!B:B,HCO_Data!K10)+COUNTIF('HCO referrals'!C:C,HCO_Data!K10) -> 2 | I10: 310783055 | K10: ID00018 | L10: Hôpital de Rangueil | M10: 1 AVENUE PR JEAN POULHES | N10: 31059 | O10: TOULOUSE | Q10: France | R10: 17 | S10: 299 | T10: 299 | V10: Yes | W10: =COUNTIFS('Clinical Trials HCO'!$A:$A, K10, 'Clinical Trials HCO'!$D:$D, "<>") -> 18 | AC10: Yes
B11: 519 | C11: Dedicated HPB surgery service states that it treats pancreatic disease surgically and explicitly describes pancreatectomy. | F11: =COUNTIF(HCPs!W:W,HCO_Data!K11) -> 4 | G11: =IF(COUNTIF('Testing Referrals'!B:B,HCO_Data!K11)>0,"Yes","") -> Yes | H11: =COUNTIF('HCO referrals'!B:B,HCO_Data!K11)+COUNTIF('HCO referrals'!C:C,HCO_Data!K11) -> 4 | I11: 250006954 | K11: ID00051 | L11: CHRU Jean Minjoz | M11: 3 BOULEVARD FLEMING | N11: 25030 | O11: BESANCON | Q11: France | R11: 13 | S11: 286 | T11: 286 | V11: Yes | W11: =COUNTIFS('Clinical Trials HCO'!$A:$A, K11, 'Clinical Trials HCO'!$D:$D, "<>") -> 23 | AG11: Yes
B12: 509 | C12: Huriez has medical oncology, pancreatic surgery, pancreatic disease/endoscopy, RCP, trials and translational research. The ARS specifically authorises the CHU Lille site for complex digestive oncological surgery including the pancreas. | F12: =COUNTIF(HCPs!W:W,HCO_Data!K12) -> 7 | G12: =IF(COUNTIF('Testing Referrals'!B:B,HCO_Data!K12)>0,"Yes","") | H12: =COUNTIF('HCO referrals'!B:B,HCO_Data!K12)+COUNTIF('HCO referrals'!C:C,HCO_Data!K12) -> 2 | I12: 590811279 | K12: ID00012 | L12: Hôpital Claude Huriez | M12: RUE MICHEL POLONOWSKI | N12: 59037 | Q12: France | R12: 28 | S12: 278 | T12: 278 | V12: Yes | W12: =COUNTIFS('Clinical Trials HCO'!$A:$A, K12, 'Clinical Trials HCO'!$D:$D, "<>") -> 20 | AC12: Yes | AF12: Yes
B13: 269 | C13: Saint-Antoine has explicit pancreatic cancer surgery through a named HPB team and integrated medical oncology/digestive care. | F13: =COUNTIF(HCPs!W:W,HCO_Data!K13) -> 4 | G13: =IF(COUNTIF('Testing Referrals'!B:B,HCO_Data!K13)>0,"Yes","") -> Yes | H13: =COUNTIF('HCO referrals'!B:B,HCO_Data!K13)+COUNTIF('HCO referrals'!C:C,HCO_Data!K13) -> 2 | I13: 750100091 | K13: ID00066 | L13: Hôpital Saint-Antoine | M13: 184 RUE DU FAUBOURG SAINT ANTOINE | N13: 75571 | O13: PARIS | Q13: France | R13: 22 | S13: 253 | T13: 253 | V13: Yes | W13: =COUNTIFS('Clinical Trials HCO'!$A:$A, K13, 'Clinical Trials HCO'!$D:$D, "<>") -> 0 | AF13: Yes | AG13: Yes
B14: 279 | C14: Paul-Brousse combines a pancreatic/HPB surgical pathway in the Centre Hépato-Biliaire with a medical oncology service explicitly treating malignant pancreatic tumours. The site also conducts pancreatic systemic-treatment research. | F14: =COUNTIF(HCPs!W:W,HCO_Data!K14) -> 7 | G14: =IF(COUNTIF('Testing Referrals'!B:B,HCO_Data!K14)>0,"Yes","") | H14: =COUNTIF('HCO referrals'!B:B,HCO_Data!K14)+COUNTIF('HCO referrals'!C:C,HCO_Data!K14) -> 1 | I14: 940100068 | K14: ID00008 | L14: Hôpital Paul Brousse | M14: 12 AVENUE PAUL VAILLANT COUTURIER | N14: 94804 | O14: VILLEJUIF | Q14: France | R14: 15 | S14: 251 | T14: 251 | V14: Yes | W14: =COUNTIFS('Clinical Trials HCO'!$A:$A, K14, 'Clinical Trials HCO'!$D:$D, "<>") -> 18 | AF14: Yes | AG14: Yes
B15: 701 | C15: CHU Reims explicitly treats pancreatic cancers, performs biliary/pancreatic ERCP, chemotherapy and endoscopy, and in 2026 launched a dedicated “Urgence tumeur pancréas” pathway for suspected pancreatic lesions with rapid access to diagnosis and treatment. | F15: =COUNTIF(HCPs!W:W,HCO_Data!K15) -> 7 | G15: =IF(COUNTIF('Testing Referrals'!B:B,HCO_Data!K15)>0,"Yes","") -> Yes | H15: =COUNTIF('HCO referrals'!B:B,HCO_Data!K15)+COUNTIF('HCO referrals'!C:C,HCO_Data!K15) -> 2 | I15: 510002447 | K15: ID00014 | L15: Hôpital Robert Debré | M15: RUE DU GENERAL KOENIG | N15: 51092 | O15: REIMS | Q15: France | R15: 9 | S15: 247 | T15: 247 | V15: Yes | W15: =COUNTIFS('Clinical Trials HCO'!$A:$A, K15, 'Clinical Trials HCO'!$D:$D, "<>") -> 32 | AG15: Yes
B16: 715 | F16: =COUNTIF(HCPs!W:W,HCO_Data!K16) -> 5 | G16: =IF(COUNTIF('Testing Referrals'!B:B,HCO_Data!K16)>0,"Yes","") | H16: =COUNTIF('HCO referrals'!B:B,HCO_Data!K16)+COUNTIF('HCO referrals'!C:C,HCO_Data!K16) -> 0 | I16: 540002698 | K16: ID00084 | L16: Hôpitaux de Brabois | M16: RUE DU MORVAN | N16: 54511 | O16: VANDOEUVRE LES NANCY | Q16: France | R16: 104 | S16: 240 | T16: 240 | V16: Yes | W16: =COUNTIFS('Clinical Trials HCO'!$A:$A, K16, 'Clinical Trials HCO'!$D:$D, "<>") -> 0 | AF16: Yes | AG16: Yes
B17: 533 | F17: =COUNTIF(HCPs!W:W,HCO_Data!K17) -> 1 | G17: =IF(COUNTIF('Testing Referrals'!B:B,HCO_Data!K17)>0,"Yes","") | H17: =COUNTIF('HCO referrals'!B:B,HCO_Data!K17)+COUNTIF('HCO referrals'!C:C,HCO_Data!K17) -> 0 | I17: 750300360 | J17: 544957847394321411 | K17: ID00153 | L17: HOPITAL PRIVE DES PEUPLIERS | M17: 8 PLACE ABBE GEORGES HENOCQUE | N17: 75013 | O17: PARIS | Q17: France | R17: 168 | S17: 235 | T17: 235 | V17: Yes | W17: =COUNTIFS('Clinical Trials HCO'!$A:$A, K17, 'Clinical Trials HCO'!$D:$D, "<>") -> 0 | AF17: Yes | AG17: Yes
B18: 44 | D18: Unicancer | F18: =COUNTIF(HCPs!W:W,HCO_Data!K18) -> 11 | G18: =IF(COUNTIF('Testing Referrals'!B:B,HCO_Data!K18)>0,"Yes","") -> Yes | H18: =COUNTIF('HCO referrals'!B:B,HCO_Data!K18)+COUNTIF('HCO referrals'!C:C,HCO_Data!K18) -> 3 | I18: 690000880 | K18: ID00029 | L18: Centre Léon Bérard | M18: 28 Prom. Léa et Napoléon Bullukian | N18: 69008 | O18: Lyon | P18: Auvergne-Rhône-Alpes | Q18: France | R18: 7 | S18: 232 | T18: 232 | V18: Yes | W18: =COUNTIFS('Clinical Trials HCO'!$A:$A, K18, 'Clinical Trials HCO'!$D:$D, "<>") -> 69 | AC18: Yes | AF18: Yes
B19: 385 | C19: The CHU's current uro-digestive oncology day hospital explicitly lists cancer du pancréas among the cancers managed, administers chemotherapy after RCP discussion, and coordinates surgery/radiotherapy/interventional radiology | F19: =COUNTIF(HCPs!W:W,HCO_Data!K19) -> 3 | G19: =IF(COUNTIF('Testing Referrals'!B:B,HCO_Data!K19)>0,"Yes","") -> Yes | H19: =COUNTIF('HCO referrals'!B:B,HCO_Data!K19)+COUNTIF('HCO referrals'!C:C,HCO_Data!K19) -> 4 | I19: 760000158 | K19: ID00017 | L19: Hôpital Charles Nicolle | M19: 1 RUE DE GERMONT | N19: 76031 | O19: ROUEN | Q19: France | R19: 30 | S19: 230 | T19: 230 | V19: Yes | W19: =COUNTIFS('Clinical Trials HCO'!$A:$A, K19, 'Clinical Trials HCO'!$D:$D, "<>") -> 12
B20: 270 | F20: =COUNTIF(HCPs!W:W,HCO_Data!K20) -> 2 | G20: =IF(COUNTIF('Testing Referrals'!B:B,HCO_Data!K20)>0,"Yes","") -> Yes | H20: =COUNTIF('HCO referrals'!B:B,HCO_Data!K20)+COUNTIF('HCO referrals'!C:C,HCO_Data!K20) -> 1 | I20: 940100027 | K20: ID00065 | L20: Hôpital Henri Mondor | M20: 51 AVENUE MAL DE LATTRE DE TASSIGNY | N20: 94010 | O20: CRETEIL | Q20: France | R20: 164 | S20: 230 | T20: 230 | V20: Yes | W20: =COUNTIFS('Clinical Trials HCO'!$A:$A, K20, 'Clinical Trials HCO'!$D:$D, "<>") -> 0 | AF20: Yes | AG20: Yes
B21: 218 | F21: =COUNTIF(HCPs!W:W,HCO_Data!K21) -> 2 | G21: =IF(COUNTIF('Testing Referrals'!B:B,HCO_Data!K21)>0,"Yes","") -> Yes | H21: =COUNTIF('HCO referrals'!B:B,HCO_Data!K21)+COUNTIF('HCO referrals'!C:C,HCO_Data!K21) -> 0 | I21: 860000223 | K21: ID00016 | L21: Hôpital de la Milétrie | M21: 2 RUE DE LA MILETRIE | N21: 86021 | O21: POITIERS | Q21: France | R21: 18 | S21: 229 | T21: 229 | V21: Yes | W21: =COUNTIFS('Clinical Trials HCO'!$A:$A, K21, 'Clinical Trials HCO'!$D:$D, "<>") -> 5 | AE21: Certified Comprehensive Cancer Centre
B22: 280 | C22: Hôpital Pitié-Salpêtrière is a major comprehensive pancreatic cancer referral and surgical centre within AP-HP. It operates a dedicated AP-HP-labelled rapid-diagnosis pancreas centre and its HPB surgical service reports more than 80 pancreatectomies for pancreatic cancer. | F22: =COUNTIF(HCPs!W:W,HCO_Data!K22) -> 7 | G22: =IF(COUNTIF('Testing Referrals'!B:B,HCO_Data!K22)>0,"Yes","") -> Yes | H22: =COUNTIF('HCO referrals'!B:B,HCO_Data!K22)+COUNTIF('HCO referrals'!C:C,HCO_Data!K22) -> 11 | I22: 750100125 | K22: ID00005 | L22: HU Pitié-Salpêtrière | M22: 47 BOULEVARD DE L HOPITAL | N22: 75651 | O22: PARIS | Q22: France | R22: 12 | S22: 227 | T22: 227 | V22: Yes | W22: =COUNTIFS('Clinical Trials HCO'!$A:$A, K22, 'Clinical Trials HCO'!$D:$D, "<>") -> 47 | AF22: Yes | AG22: Yes
B23: 656 | C23: Hôpital Saint-Éloi is a major pancreatic cancer centre within CHU de Montpellier, with pancreatic diagnosis, advanced endoscopy, pancreatic surgery and medical oncology all directly documented on the Saint-Éloi site. | F23: =COUNTIF(HCPs!W:W,HCO_Data!K23) -> 8 | G23: =IF(COUNTIF('Testing Referrals'!B:B,HCO_Data!K23)>0,"Yes","") -> Yes | H23: =COUNTIF('HCO referrals'!B:B,HCO_Data!K23)+COUNTIF('HCO referrals'!C:C,HCO_Data!K23) -> 4 | I23: 340782036 | K23: ID00004 | L23: Hôpital Saint-Eloi | M23: 80 AVENUE AUGUSTIN FLICHE | N23: 34295 | O23: MONTPELLIER | Q23: France | R23: 40 | S23: 225 | T23: 225 | V23: Yes | W23: =COUNTIFS('Clinical Trials HCO'!$A:$A, K23, 'Clinical Trials HCO'!$D:$D, "<>") -> 9 | AC23: Yes | AG23: Yes
B24: 219 | C24: The CHU HGE service explicitly manages pancreatic diseases and pancreatic cancer, provides digestive oncology, and is a regional expert centre for diagnostic/therapeutic/interventional echo-endoscopy. Its digestive surgery service explicitly covers pancreatic oncologic surgery. | F24: =COUNTIF(HCPs!W:W,HCO_Data!K24) -> 2 | G24: =IF(COUNTIF('Testing Referrals'!B:B,HCO_Data!K24)>0,"Yes","") -> Yes | H24: =COUNTIF('HCO referrals'!B:B,HCO_Data!K24)+COUNTIF('HCO referrals'!C:C,HCO_Data!K24) -> 2 | I24: 300782117 | K24: ID00073 | L24: CHU Carémeau | M24: PLACE DU PROFESSEUR ROBERT DEBRE | N24: 30029 | O24: NIMES | Q24: France | R24: 23 | S24: 224 | T24: 224 | V24: Yes | W24: =COUNTIFS('Clinical Trials HCO'!$A:$A, K24, 'Clinical Trials HCO'!$D:$D, "<>") -> 3 | AF24: Yes | AG24: Yes
B25: 272 | C25: Cochin has site-level pancreatic surgery, digestive oncology and specialised pancreaticobiliary endoscopy. A dedicated rapid diagnostic pathway links gastroenterology, surgery, pathology and imaging. | F25: =COUNTIF(HCPs!W:W,HCO_Data!K25) -> 11 | G25: =IF(COUNTIF('Testing Referrals'!B:B,HCO_Data!K25)>0,"Yes","") -> Yes | H25: =COUNTIF('HCO referrals'!B:B,HCO_Data!K25)+COUNTIF('HCO referrals'!C:C,HCO_Data!K25) -> 0 | I25: 750100166 | K25: ID00009 | L25: Hôpital Cochin | M25: 27 RUE DU FAUBOURG SAINT JACQUES | N25: 75679 | O25: PARIS | Q25: France | R25: 19 | S25: 221 | T25: 221 | V25: Yes | W25: =COUNTIFS('Clinical Trials HCO'!$A:$A, K25, 'Clinical Trials HCO'!$D:$D, "<>") -> 25 | AF25: Yes | AG25: Yes
B26: 342 | F26: =COUNTIF(HCPs!W:W,HCO_Data!K26) -> 6 | G26: =IF(COUNTIF('Testing Referrals'!B:B,HCO_Data!K26)>0,"Yes","") -> Yes | H26: =COUNTIF('HCO referrals'!B:B,HCO_Data!K26)+COUNTIF('HCO referrals'!C:C,HCO_Data!K26) -> 5 | I26: 630781268 | K26: ID00047 | L26: CHU Estaing | M26: 1 PLACE LUCIE AUBRAC | N26: 63003 | O26: CLERMONT FERRAND | Q26: France | R26: 26 | S26: 219 | T26: 219 | V26: Yes | W26: =COUNTIFS('Clinical Trials HCO'!$A:$A, K26, 'Clinical Trials HCO'!$D:$D, "<>") -> 12 | AF26: Yes | AG26: Yes
B27: 295 | F27: =COUNTIF(HCPs!W:W,HCO_Data!K27) -> 3 | G27: =IF(COUNTIF('Testing Referrals'!B:B,HCO_Data!K27)>0,"Yes","") -> Yes | H27: =COUNTIF('HCO referrals'!B:B,HCO_Data!K27)+COUNTIF('HCO referrals'!C:C,HCO_Data!K27) -> 0 | I27: 420785354 | J27: 544957037222560785 | K27: ID00042 | L27: Hôpital Nord | M27: AVENUE ALBERT RAIMOND | N27: 42277 | O27: SAINT PRIEST EN JAREZ | Q27: France | R27: 24 | S27: 214 | T27: 214 | V27: Yes | W27: =COUNTIFS('Clinical Trials HCO'!$A:$A, K27, 'Clinical Trials HCO'!$D:$D, "<>") -> 0 | AG27: Yes
B28: 227 | C28: Gastroenterology treats pancreatic malignancy and pancreatic disease. The surgery page explicitly includes pancreatic cancer. | F28: =COUNTIF(HCPs!W:W,HCO_Data!K28) -> 1 | G28: =IF(COUNTIF('Testing Referrals'!B:B,HCO_Data!K28)>0,"Yes","") | H28: =COUNTIF('HCO referrals'!B:B,HCO_Data!K28)+COUNTIF('HCO referrals'!C:C,HCO_Data!K28) -> 2 | I28: 310780259 | J28: 544958368821806083 | K28: ID00130 | L28: Clinique Pasteur Toulouse | M28: 45 AVENUE DE LOMBEZ | N28: 31076 | O28: TOULOUSE | Q28: France | R28: 44 | S28: 209 | T28: 209 | V28: Yes | W28: =COUNTIFS('Clinical Trials HCO'!$A:$A, K28, 'Clinical Trials HCO'!$D:$D, "<>") -> 5 | AF28: Yes | AG28: Yes
C29: HEGP has documented pancreatic cancer activity across medical oncology, digestive surgery and pancreaticobiliary gastroenterology/endoscopy. The oncology service also conducts clinical research. | F29: =COUNTIF(HCPs!W:W,HCO_Data!K29) -> 4 | G29: =IF(COUNTIF('Testing Referrals'!B:B,HCO_Data!K29)>0,"Yes","") -> Yes | H29: =COUNTIF('HCO referrals'!B:B,HCO_Data!K29)+COUNTIF('HCO referrals'!C:C,HCO_Data!K29) -> 2 | I29: 750803447 | J29: 608464600169464832 | K29: ID00010 | L29: Hôpital Européen Georges-Pompidou | O29: PARIS | Q29: France | R29: 8 | S29: 208 | T29: 208 | V29: Yes | W29: =COUNTIFS('Clinical Trials HCO'!$A:$A, K29, 'Clinical Trials HCO'!$D:$D, "<>") -> 24 | AF29: Yes
B30: 294 | F30: =COUNTIF(HCPs!W:W,HCO_Data!K30) -> 3 | G30: =IF(COUNTIF('Testing Referrals'!B:B,HCO_Data!K30)>0,"Yes","") -> Yes | H30: =COUNTIF('HCO referrals'!B:B,HCO_Data!K30)+COUNTIF('HCO referrals'!C:C,HCO_Data!K30) -> 2 | I30: 380000067 | K30: ID00036 | L30: Hôpital Albert Michallon | M30: BOULEVARD DE LA CHANTOURNE | N30: 38700 | O30: LA TRONCHE | Q30: France | R30: 16 | S30: 205 | T30: 205 | V30: Yes | W30: =COUNTIFS('Clinical Trials HCO'!$A:$A, K30, 'Clinical Trials HCO'!$D:$D, "<>") -> 0 | AF30: Yes
B31: 456 | C31: Institut Strauss explicitly lists pancreatic cancer among cancers treated and has a current pancreatic-specific oncologist and pancreatic clinical-trial activity. | D31: Unicancer | F31: =COUNTIF(HCPs!W:W,HCO_Data!K31) -> 5 | G31: =IF(COUNTIF('Testing Referrals'!B:B,HCO_Data!K31)>0,"Yes","") | H31: =COUNTIF('HCO referrals'!B:B,HCO_Data!K31)+COUNTIF('HCO referrals'!C:C,HCO_Data!K31) -> 5 | I31: 670020098 | K31: ID00081 | L31: ICANS Strasbourg | M31: 17 RUE ALBERT CALMETTE | N31: 67200 | O31: STRASBOURG | Q31: France | R31: 11 | S31: 205 | T31: 205 | V31: Yes | W31: =COUNTIFS('Clinical Trials HCO'!$A:$A, K31, 'Clinical Trials HCO'!$D:$D, "<>") -> 14 | AD31: Yes | AE31: Certified Comprehensive Cancer Centre | AF31: Yes | AG31: Yes
B32: 114 | C32: CHU explicitly states that its digestive cancer programme includes pancreatic cancer, with diagnosis, surgery, chemotherapy/targeted therapy and weekly digestive cancer RCP. Its digestive surgery service explicitly lists cancer du pancréas and describes itself as a digestive oncology expert/referral centre. | F32: =COUNTIF(HCPs!W:W,HCO_Data!K32) -> 6 | G32: =IF(COUNTIF('Testing Referrals'!B:B,HCO_Data!K32)>0,"Yes","") -> Yes | H32: =COUNTIF('HCO referrals'!B:B,HCO_Data!K32)+COUNTIF('HCO referrals'!C:C,HCO_Data!K32) -> 1 | I32: 210987558 | K32: ID00052 | L32: CHRU le Bocage | M32: 1 BOULEVARD JEANNE D ARC | N32: 21079 | O32: DIJON | Q32: France | R32: 39 | S32: 198 | T32: 198 | V32: Yes | W32: =COUNTIFS('Clinical Trials HCO'!$A:$A, K32, 'Clinical Trials HCO'!$D:$D, "<>") -> 0 | AF32: Yes | AG32: Yes
B33: 115 | F33: =COUNTIF(HCPs!W:W,HCO_Data!K33) -> 4 | G33: =IF(COUNTIF('Testing Referrals'!B:B,HCO_Data!K33)>0,"Yes","") -> Yes | H33: =COUNTIF('HCO referrals'!B:B,HCO_Data!K33)+COUNTIF('HCO referrals'!C:C,HCO_Data!K33) -> 0 | I33: 870000064 | K33: ID00039 | L33: Hôpital Dupuytren | M33: 2 AVENUE MARTIN LUTHER KING | N33: 87042 | O33: LIMOGES | Q33: France | R33: 46 | S33: 197 | T33: 197 | V33: Yes | W33: =COUNTIFS('Clinical Trials HCO'!$A:$A, K33, 'Clinical Trials HCO'!$D:$D, "<>") -> 0 | AF33: Yes | AG33: Yes
B34: 10 | D34: Unicancer | F34: =COUNTIF(HCPs!W:W,HCO_Data!K34) -> 5 | G34: =IF(COUNTIF('Testing Referrals'!B:B,HCO_Data!K34)>0,"Yes","") -> Yes | H34: =COUNTIF('HCO referrals'!B:B,HCO_Data!K34)+COUNTIF('HCO referrals'!C:C,HCO_Data!K34) -> 0 | I34: 210987731 | K34: ID00053 | L34: Centre Georges-François Leclerc | O34: DIJON | Q34: France | R34: 10 | S34: 195 | T34: 195 | V34: Yes | W34: =COUNTIFS('Clinical Trials HCO'!$A:$A, K34, 'Clinical Trials HCO'!$D:$D, "<>") -> 44 | AF34: Yes | AG34: Yes
B35: 18 | F35: =COUNTIF(HCPs!W:W,HCO_Data!K35) -> 5 | G35: =IF(COUNTIF('Testing Referrals'!B:B,HCO_Data!K35)>0,"Yes","") -> Yes | H35: =COUNTIF('HCO referrals'!B:B,HCO_Data!K35)+COUNTIF('HCO referrals'!C:C,HCO_Data!K35) -> 0 | I35: 690783154 | K35: ID00013 | L35: Hôpital Édouard Herriot | O35: LYON | Q35: France | R35: 49 | S35: 192 | T35: 192 | V35: Yes | W35: =COUNTIFS('Clinical Trials HCO'!$A:$A, K35, 'Clinical Trials HCO'!$D:$D, "<>") -> 36 | AG35: Yes
B36: 216 | C36: Digestive oncology is delivered locally through consultation, day-hospital and weekly hospitalisation. Have dedicated pancreatic surgery and pancreatic diseases consultation. | F36: =COUNTIF(HCPs!W:W,HCO_Data!K36) -> 5 | G36: =IF(COUNTIF('Testing Referrals'!B:B,HCO_Data!K36)>0,"Yes","") | H36: =COUNTIF('HCO referrals'!B:B,HCO_Data!K36)+COUNTIF('HCO referrals'!C:C,HCO_Data!K36) -> 1 | I36: 140000209 | K36: ID00104 | L36: Hôpital de la Côte de Nacre | M36: AVENUE COTE DE NACRE | N36: 14033 | O36: CAEN | Q36: France | R36: 36 | S36: 191 | T36: 191 | V36: Yes | W36: =COUNTIFS('Clinical Trials HCO'!$A:$A, K36, 'Clinical Trials HCO'!$D:$D, "<>") -> 6 | AF36: Yes | AG36: Yes
F37: =COUNTIF(HCPs!W:W,HCO_Data!K37) -> 2 | G37: =IF(COUNTIF('Testing Referrals'!B:B,HCO_Data!K37)>0,"Yes","") -> Yes | H37: =COUNTIF('HCO referrals'!B:B,HCO_Data!K37)+COUNTIF('HCO referrals'!C:C,HCO_Data!K37) -> 0 | I37: 800006124 | K37: ID00035 | L37: Hôpital Sud | M37: 1 Rue du Professeur Christian Cabrol | O37: Amiens | Q37: France | R37: 29 | S37: 190 | T37: 190 | V37: Yes | W37: =COUNTIFS('Clinical Trials HCO'!$A:$A, K37, 'Clinical Trials HCO'!$D:$D, "<>") -> 0
B38: 211 | F38: =COUNTIF(HCPs!W:W,HCO_Data!K38) -> 3 | G38: =IF(COUNTIF('Testing Referrals'!B:B,HCO_Data!K38)>0,"Yes","") -> Yes | H38: =COUNTIF('HCO referrals'!B:B,HCO_Data!K38)+COUNTIF('HCO referrals'!C:C,HCO_Data!K38) -> 2 | I38: 490000049 | K38: ID00076 | L38: CHU Hôtel-Dieu | M38: 4 RUE LARREY | N38: 49933 | O38: ANGERS | Q38: France | R38: 57 | S38: 182 | T38: 182 | V38: Yes | W38: =COUNTIFS('Clinical Trials HCO'!$A:$A, K38, 'Clinical Trials HCO'!$D:$D, "<>") -> 2 | AF38: Yes | AG38: Yes
B39: 541 | F39: =COUNTIF(HCPs!W:W,HCO_Data!K39) -> 2 | G39: =IF(COUNTIF('Testing Referrals'!B:B,HCO_Data!K39)>0,"Yes","") | H39: =COUNTIF('HCO referrals'!B:B,HCO_Data!K39)+COUNTIF('HCO referrals'!C:C,HCO_Data!K39) -> 0 | I39: 440041580 | J39: 544957509996119053 | K39: ID00154 | L39: HOPITAL PRIVE DU CONFLUENT | M39: 4 RUE ERIC TABARLY | N39: 44277 | O39: NANTES | Q39: France | R39: 37 | S39: 180 | T39: 180 | V39: Yes | W39: =COUNTIFS('Clinical Trials HCO'!$A:$A, K39, 'Clinical Trials HCO'!$D:$D, "<>") -> 0 | AF39: Yes | AG39: Yes
B40: 483 | C40: The European Hospital has established an emergency pathway dedicated to the rapid diagnosis and treatment of suspected tumors and cancer, including pancreatic cancer. | F40: =COUNTIF(HCPs!W:W,HCO_Data!K40) -> 7 | G40: =IF(COUNTIF('Testing Referrals'!B:B,HCO_Data!K40)>0,"Yes","") | H40: =COUNTIF('HCO referrals'!B:B,HCO_Data!K40)+COUNTIF('HCO referrals'!C:C,HCO_Data!K40) -> 0 | I40: 130043664 | K40: ID00123 | L40: Hôpital Européen | M40: 6 RUE DÉSIRÉE CLARY | N40: 13003 | O40: MARSEILLE | Q40: France | R40: 34 | S40: 176 | T40: 176 | V40: Yes | W40: =COUNTIFS('Clinical Trials HCO'!$A:$A, K40, 'Clinical Trials HCO'!$D:$D, "<>") -> 11
...

Sheet Clinical Trials HCO
A1: HCO ID | B1: HCO name | C1: Location | D1: Clinical Trials_link | E1: Clinical Trials_name | F1: Clinical Trials_Sponsor | G1: KRAS mutation | H1: Metastatic | I1: Unreseclatble | J1: PDAC or Pancreatic Adenocarcinoma | K1: Pancreatic ductal adenocarcinoma | L1: Pancreatic adenocarcinoma | M1: Pancreatic Cancer
B2: filter | D2: filter | E2: filter | F2: filter | G2: filter | H2: filter | I2: filter | J2: filter | K2: filter | L2: filter | M2: filter
A3: ID00071 | B3: Institut Bergonié | C3: Institut Bergonnie, Bordeaux, 33076, France | D3: https://clinicaltrials.gov/study/NCT02602067 | E3: 131Iodine-Tenatumomab Treatment in Tenascin-C Positive Cancer Patients | F3: sigma-tau i.f.r. S.p.A.
A4: ID00029 | B4: Centre Léon Bérard | C4: Centre Leon Berard, Lyon, 69373, France | D4: https://clinicaltrials.gov/study/NCT02602067 | E4: 131Iodine-Tenatumomab Treatment in Tenascin-C Positive Cancer Patients | F4: sigma-tau i.f.r. S.p.A.
C5: Ambroise Pare Hospital, Boulogne-Billancourt, Haut de Seine, 92100, France | D5: https://clinicaltrials.gov/study/NCT04294589 | E5: Evaluation of NETs in Patients With Solid Cancers Associated With a High Risk of Venous Thromboembolic Events | F5: Assistance Publique - Hôpitaux de Paris | M5: Yes
C6: Ambroise Paré-Hartmann, Neuilly, 92200, France | D6: https://clinicaltrials.gov/study/NCT05059444 | E6: ORACLE: Observation of ResiduAl Cancer With Liquid Biopsy Evaluation | F6: Guardant Health, Inc. | L6: Yes
C7: American Hospital of Paris, Neuilly-sur-Seine, F-92202, France | D7: https://clinicaltrials.gov/study/NCT00010088 | E7: Chemotherapy in Treating Patients With Locally Advanced or Metastatic Cancer of the Pancreas or Bile Duct | F7: GERCOR - Multidisciplinary Oncology Cooperative Group | H7: Yes | M7: Yes
A8: ID00001 | B8: Hôpital Beaujon | C8: Hôpital Beaujon APHP, Clichy, France, 92110, France | D8: https://clinicaltrials.gov/study/NCT01485679 | E8: 18 Fluoro-deoxy-glucose Positrons Emission Tomography Combined With Computed Tomography (18-FDG TEP-CT ) in the Diagnosis of the Degeneration of Intraductal Papillary Mucinous Tumor of the Pancreas | F8: Nantes University Hospital
A9: ID00012 | B9: Hôpital Claude Huriez | C9: Hôpital C Huriez, Lille, France, 59037, France | D9: https://clinicaltrials.gov/study/NCT01485679 | E9: 18 Fluoro-deoxy-glucose Positrons Emission Tomography Combined With Computed Tomography (18-FDG TEP-CT ) in the Diagnosis of the Degeneration of Intraductal Papillary Mucinous Tumor of the Pancreas | F9: Nantes University Hospital
C10: American Hospital of Paris, Neuilly-sur-Seine, F-92202, France | D10: https://clinicaltrials.gov/study/NCT00006117 | E10: Gemcitabine and Oxaliplatin in Treating Patients With Locally Advanced or Metastatic Pancreatic Cancer | F10: GERCOR - Multidisciplinary Oncology Cooperative Group | H10: Yes | M10: Yes
A11: ID00011 | B11: Institut Paoli-Calmettes | C11: Institut Paoli Calmettes, Marseille, France, 13273, France | D11: https://clinicaltrials.gov/study/NCT01485679 | E11: 18 Fluoro-deoxy-glucose Positrons Emission Tomography Combined With Computed Tomography (18-FDG TEP-CT ) in the Diagnosis of the Degeneration of Intraductal Papillary Mucinous Tumor of the Pancreas | F11: Nantes University Hospital
C12: American Hospital of Paris, Neuilly-sur-Seine, F-92202, France | D12: https://clinicaltrials.gov/study/NCT00075452 | E12: Gemcitabine With or Without Oxaliplatin in Treating Patients With Locally Advanced or Metastatic Unresectable Pancreatic Adenocarcinoma | F12: GERCOR - Multidisciplinary Oncology Cooperative Group | H12: Yes | I12: Yes | L12: Yes | M12: Yes
C13: Angers, 49933, France | D13: https://clinicaltrials.gov/study/NCT00652366 | E13: A Dose-Escalation to Rash Study of Tarceva (Erlotinib) Plus Gemcitabine in Patients With Metastatic Pancreatic Cancer | F13: Hoffmann-La Roche | H13: Yes | M13: Yes
C14: Angers, Maine-et-Loire, 49933, France | D14: https://clinicaltrials.gov/study/NCT01395017 | E14: Dasatinib Added to Gemcitabine for Subjects With Locally-advanced Pancreatic Cancer | F14: Otsuka Pharmaceutical Development & Commercialization, Inc. | M14: Yes
A15: ID00002 | B15: Hôpital de Hautepierre | C15: Hôpital de Hautepierre, Strasbourg, France, 67098, France | D15: https://clinicaltrials.gov/study/NCT01485679 | E15: 18 Fluoro-deoxy-glucose Positrons Emission Tomography Combined With Computed Tomography (18-FDG TEP-CT ) in the Diagnosis of the Degeneration of Intraductal Papillary Mucinous Tumor of the Pancreas | F15: Nantes University Hospital
C16: AP-HM, Marseille, 13005, France | D16: https://clinicaltrials.gov/study/NCT03906331 | E16: Expanded Access for the Treatment of Cancers With Rearranged During Transfection (RET) Activation | F16: Eli Lilly and Company | M16: Yes
A17: ID00018 | B17: Hôpital de Rangueil | C17: CHU Rangueil, Toulouse, 31059, France | D17: https://clinicaltrials.gov/study/NCT01485679 | E17: 18 Fluoro-deoxy-glucose Positrons Emission Tomography Combined With Computed Tomography (18-FDG TEP-CT ) in the Diagnosis of the Degeneration of Intraductal Papillary Mucinous Tumor of the Pancreas | F17: Nantes University Hospital
C18: APHM, Marseille, France | D18: https://clinicaltrials.gov/study/NCT05470738 | E18: PAncreas Borderline and Locally Advanced Snapshot Study | F18: University Hospital, Clermont-Ferrand | L18: Yes | M18: Yes
A19: ID00067 | B19: Hôpital Tenon | C19: APHP Tenon Hospital - Sorbonne, Paris, 75020, France | D19: https://clinicaltrials.gov/study/NCT05059444 | E19: ORACLE: Observation of ResiduAl Cancer With Liquid Biopsy Evaluation | F19: Guardant Health, Inc. | L19: Yes
A20: ID00012 | B20: Hôpital Claude Huriez | C20: Hopital Claude Huriez, Lille, Hauts-de-France, 59037, France | D20: https://clinicaltrials.gov/study/NCT03678883 | E20: 9-ING-41 in Patients With Advanced Cancers | F20: Actuate Therapeutics Inc. | L20: Yes | M20: Yes
C21: Assistance Publique - Hopitaux de Marseille (Ap-Hm, Marseille, 13009, France | D21: https://clinicaltrials.gov/study/NCT06177327 | E21: Hepato-pancreato-biliary Abnormalities in Fibrous Dysplasia of Bone/McCune Albright Syndrome | F21: Hospices Civils de Lyon
A22: ID00071 | B22: Institut Bergonié | C22: Institut Bergonie, Bordeaux, New Aquitaine, 33076, France | D22: https://clinicaltrials.gov/study/NCT03678883 | E22: 9-ING-41 in Patients With Advanced Cancers | F22: Actuate Therapeutics Inc. | L22: Yes | M22: Yes
C23: Assistance Publique - Hopitaux de Paris (Ap-Hp), Paris, 75010, France | D23: https://clinicaltrials.gov/study/NCT06177327 | E23: Hepato-pancreato-biliary Abnormalities in Fibrous Dysplasia of Bone/McCune Albright Syndrome | F23: Hospices Civils de Lyon
A24: ID00032 | B24: Hôpital de la Timone Adulte | C24: Hopital de la Timone, Marseille, 13005, France | D24: https://clinicaltrials.gov/study/NCT03678883 | E24: 9-ING-41 in Patients With Advanced Cancers | F24: Actuate Therapeutics Inc. | L24: Yes | M24: Yes
C25: Assistance Publique des Hôpitaux de Marseille, Marseille, 13000, France | D25: https://clinicaltrials.gov/study/NCT00789633 | E25: Masitinib in Combination With Gemcitabine for Treatment of Patients With Advanced/Metastatic Pancreatic Cancer | F25: AB Science | H25: Yes | M25: Yes
A26: ID00079 | B26: Centre Antoine Lacassagne | C26: Centre Antoine Lacassagne, Nice, Cedex 02, 06189, France | D26: https://clinicaltrials.gov/study/NCT00428220 | E26: A Continuation Study Using Sunitinib Malate For Patients Leaving Treatment On A Previous Sunitinib Study. | F26: Pfizer | H26: Yes
A27: ID00001 | B27: Hôpital Beaujon | C27: Hopital Beaujon, Clichy, Cedex, 92118, France | D27: https://clinicaltrials.gov/study/NCT00428220 | E27: A Continuation Study Using Sunitinib Malate For Patients Leaving Treatment On A Previous Sunitinib Study. | F27: Pfizer | H27: Yes
A28: ID00009 | B28: Hôpital Cochin | C28: Groupe Hospitalier Cochin, Cancer Quest AP-HP, Paris, Cedex, 75679, France | D28: https://clinicaltrials.gov/study/NCT00428220 | E28: A Continuation Study Using Sunitinib Malate For Patients Leaving Treatment On A Previous Sunitinib Study. | F28: Pfizer | H28: Yes
C29: Assistance Publique des Hôpitaux de Marseille, Marseille, Bouches du Rhône, 13385, France | D29: https://clinicaltrials.gov/study/NCT02858141 | E29: Onco-geriatric Database of Patients With Pancreatic Cancer | F29: Institut Paoli-Calmettes | M29: Yes
C30: Assistance Publique Hôpitaux de Marseille | D30: =_xlfn.XLOOKUP(E30,HCP_evidence!H:H,HCP_evidence!I:I) -> #N/A | E30: A multicenter, open-label, non-randomized, Phase 1/2 study to evaluate the safety, tolerability, and imaging characteristics of [68Ga]Ga-DPI-4452 and to evaluate the safety, tolerability, and efficacy of [177Lu]Lu-DPI-4452 in patients with locally advanced or unresectable metastatic solid tumors. | G30: {=_xlfn.XLOOKUP(E30,HCP_evidence!H:H,IF(HCP_evidence!M:M="Yes","Yes",""))} -> #N/A | H30: {=_xlfn.XLOOKUP(E30,HCP_evidence!H:H,IF(HCP_evidence!K:K="Yes","Yes",""))} -> #N/A | I30: {=_xlfn.XLOOKUP(E30,HCP_evidence!H:H,IF(HCP_evidence!J:J="Yes","Yes",""))} -> #N/A | J30: =IF(OR(K30="Yes",L30="Yes"),"Yes","") -> #REF! | K30: {=_xlfn.XLOOKUP(E30,HCP_evidence!H:H,IF(HCP_evidence!#REF!="Yes","Yes",""))} -> #REF! | L30: {=_xlfn.XLOOKUP(E30,HCP_evidence!H:H,IF(HCP_evidence!#REF!="Yes","Yes",""))} -> #REF! | M30: {=_xlfn.XLOOKUP(E30,HCP_evidence!H:H,IF(HCP_evidence!N:N="Yes","Yes",""))} -> #N/A
A31: ID00049 | B31: Centre Jean Perrin | C31: Centre Jean Perrin, Clermont-Ferrand, 63011, France | D31: https://clinicaltrials.gov/study/NCT00428220 | E31: A Continuation Study Using Sunitinib Malate For Patients Leaving Treatment On A Previous Sunitinib Study. | F31: Pfizer | H31: Yes
C32: Assistance Publique Hôpitaux de Marseille | D32: =_xlfn.XLOOKUP(E32,HCP_evidence!H:H,HCP_evidence!I:I) -> #N/A | E32: A Phase I, Open-Label, Multicenter Study to Evaluate the Safety, Tolerability, Dosimetry, and Preliminary Activity of [177Lu]Lu-DFC413, and the Safety and Imaging Properties of [68Ga]Ga-NNS309 in Patients With Solid Tumors | G32: {=_xlfn.XLOOKUP(E32,HCP_evidence!H:H,IF(HCP_evidence!M:M="Yes","Yes",""))} -> #N/A | H32: {=_xlfn.XLOOKUP(E32,HCP_evidence!H:H,IF(HCP_evidence!K:K="Yes","Yes",""))} -> #N/A | I32: {=_xlfn.XLOOKUP(E32,HCP_evidence!H:H,IF(HCP_evidence!J:J="Yes","Yes",""))} -> #N/A | J32: =IF(OR(K32="Yes",L32="Yes"),"Yes","") -> #REF! | K32: {=_xlfn.XLOOKUP(E32,HCP_evidence!H:H,IF(HCP_evidence!#REF!="Yes","Yes",""))} -> #REF! | L32: {=_xlfn.XLOOKUP(E32,HCP_evidence!H:H,IF(HCP_evidence!#REF!="Yes","Yes",""))} -> #REF! | M32: {=_xlfn.XLOOKUP(E32,HCP_evidence!H:H,IF(HCP_evidence!N:N="Yes","Yes",""))} -> #N/A
A33: ID00046 | B33: Centre Oscar Lambret | C33: Centre Oscar Lambret, Lille, 59020, France | D33: https://clinicaltrials.gov/study/NCT00428220 | E33: A Continuation Study Using Sunitinib Malate For Patients Leaving Treatment On A Previous Sunitinib Study. | F33: Pfizer | H33: Yes
A34: ID00029 | B34: Centre Léon Bérard | C34: Centre Leon Berard, Lyon, 69008, France | D34: https://clinicaltrials.gov/study/NCT00428220 | E34: A Continuation Study Using Sunitinib Malate For Patients Leaving Treatment On A Previous Sunitinib Study. | F34: Pfizer | H34: Yes
A35: ID00013 | B35: Hôpital Édouard Herriot | C35: Hopital Edouard Herriot, Lyon, 69437, France | D35: https://clinicaltrials.gov/study/NCT00428220 | E35: A Continuation Study Using Sunitinib Malate For Patients Leaving Treatment On A Previous Sunitinib Study. | F35: Pfizer | H35: Yes
A36: ID00032 | B36: Hôpital de la Timone Adulte | C36: Chu La Timone, Marseille, 13385, France | D36: https://clinicaltrials.gov/study/NCT00428220 | E36: A Continuation Study Using Sunitinib Malate For Patients Leaving Treatment On A Previous Sunitinib Study. | F36: Pfizer | H36: Yes
C37: Assistance Publique Hopitaux de Marseille Hopitaux Sud, Marseille, 13274, France | D37: https://clinicaltrials.gov/study/NCT00010088 | E37: Chemotherapy in Treating Patients With Locally Advanced or Metastatic Cancer of the Pancreas or Bile Duct | F37: GERCOR - Multidisciplinary Oncology Cooperative Group | H37: Yes | M37: Yes
C38: Assistance Publique Hopitaux de Marseille, Marseille, 13005, France | D38: https://clinicaltrials.gov/study/NCT02150408 | E38: Evaluation of PET-CT Using Somatostatin Agonists Labeled With Gallium68 in Neuroendocrine Tumors | F38: Assistance Publique Hopitaux De Marseille
C39: Aurélien DUPRE, Lyon, 69008, France | D39: https://clinicaltrials.gov/study/NCT07144917 | E39: Immunoparalysis After Pancreaticoduodenectomy | F39: Hospices Civils de Lyon | K39: Yes | L39: Yes
C40: Barthet, Marseille, 13000, France | D40: https://clinicaltrials.gov/study/NCT02330497 | E40: Efficacy and Safety of Radiofrequency Ablation in Pancreatic Neuroendocrine and Cystic Tumor | F40: Société Française d'Endoscopie Digestive | I40: Yes
...

Sheet HCO referrals
A1: Path_ID | B1: From_Hospital_ID | C1: To_Hospital_ID | D1: Connection_Type | E1: Strength | F1: Source
A2: =B2&"-"&C2&"-"&SUBSTITUTE(D2," ", "-") -> ID00043-ID00038-Collaboration | B2: ID00043 | C2: ID00038 | D2: Collaboration | E2: 1 | F2: https://curie.fr/symptomes-et-diagnostic-du-cancer-du-pancreas#content
A3: =B3&"-"&C3&"-"&SUBSTITUTE(D3," ", "-") -> ID00038-ID00043-Collaboration | B3: ID00038 | C3: ID00043 | D3: Collaboration | E3: 1 | F3: https://curie.fr/symptomes-et-diagnostic-du-cancer-du-pancreas#content
A4: =B4&"-"&C4&"-"&SUBSTITUTE(D4," ", "-") -> ID00002-ID00006-Referral | B4: ID00002 | C4: ID00006 | D4: Referral | E4: 1 | F4: https://www.chru-strasbourg.fr/service/gastro-enterologie/
A5: =B5&"-"&C5&"-"&SUBSTITUTE(D5," ", "-") -> ID00006-ID00002-Surgery | B5: ID00006 | C5: ID00002 | D5: Surgery | E5: 1 | F5: https://www.chru-strasbourg.fr/service/gastro-enterologie/
A6: =B6&"-"&C6&"-"&SUBSTITUTE(D6," ", "-") -> ID00004-ID00026-Collaboration | B6: ID00004 | C6: ID00026 | D6: Collaboration | E6: 1
A7: =B7&"-"&C7&"-"&SUBSTITUTE(D7," ", "-") -> ID00026-ID00004-Collaboration | B7: ID00026 | C7: ID00004 | D7: Collaboration | E7: 1
A8: =B8&"-"&C8&"-"&SUBSTITUTE(D8," ", "-") -> ID00004-ID00012-Collaboration | B8: ID00004 | C8: ID00012 | D8: Collaboration | E8: 1 | F8: https://www.chu-montpellier.fr/fr/information-transversale/actualites/autogreffe-dilots-de-langerhans-une-procedure-exceptionnelle-promu-a-un-fort-developpement-7253
A9: =B9&"-"&C9&"-"&SUBSTITUTE(D9," ", "-") -> ID00012-ID00004-Collaboration | B9: ID00012 | C9: ID00004 | D9: Collaboration | E9: 1 | F9: https://www.chu-montpellier.fr/fr/information-transversale/actualites/autogreffe-dilots-de-langerhans-une-procedure-exceptionnelle-promu-a-un-fort-developpement-7253
A10: =B10&"-"&C10&"-"&SUBSTITUTE(D10," ", "-") -> ID00089-ID00005-Collaboration | B10: ID00089 | C10: ID00005 | D10: Collaboration | E10: 1 | F10: https://www.aphp.fr/pitie-salpetriere/service-d-oncologie-medicale
A11: =B11&"-"&C11&"-"&SUBSTITUTE(D11," ", "-") -> ID00005-ID00089-Collaboration | B11: ID00005 | C11: ID00089 | D11: Collaboration | E11: 1 | F11: https://www.aphp.fr/pitie-salpetriere/service-d-oncologie-medicale
A12: =B12&"-"&C12&"-"&SUBSTITUTE(D12," ", "-") -> ID00090-ID00005-Collaboration | B12: ID00090 | C12: ID00005 | D12: Collaboration | E12: 1 | F12: https://www.aphp.fr/pitie-salpetriere/service-d-oncologie-medicale
A13: =B13&"-"&C13&"-"&SUBSTITUTE(D13," ", "-") -> ID00005-ID00090-Collaboration | B13: ID00005 | C13: ID00090 | D13: Collaboration | E13: 1 | F13: https://www.aphp.fr/pitie-salpetriere/service-d-oncologie-medicale
A14: =B14&"-"&C14&"-"&SUBSTITUTE(D14," ", "-") -> ID00065-ID00005-Referral | B14: ID00065 | C14: ID00005 | D14: Referral | E14: 1 | F14: https://www.aphp.fr/registre-des-essais-cliniques/tepirm-dans-levaluation-de-la-reponse-au-traitement-neoadjuvant-de
A15: =B15&"-"&C15&"-"&SUBSTITUTE(D15," ", "-") -> ID00008-ID00005-Referral | B15: ID00008 | C15: ID00005 | D15: Referral | E15: 1 | F15: https://www.aphp.fr/registre-des-essais-cliniques/tepirm-dans-levaluation-de-la-reponse-au-traitement-neoadjuvant-de
A16: =B16&"-"&C16&"-"&SUBSTITUTE(D16," ", "-") -> ID00001-ID00005-Referral | B16: ID00001 | C16: ID00005 | D16: Referral | E16: 1 | F16: https://www.aphp.fr/registre-des-essais-cliniques/tepirm-dans-levaluation-de-la-reponse-au-traitement-neoadjuvant-de
A17: =B17&"-"&C17&"-"&SUBSTITUTE(D17," ", "-") -> ID00066-ID00005-Referral | B17: ID00066 | C17: ID00005 | D17: Referral | E17: 1 | F17: https://www.aphp.fr/registre-des-essais-cliniques/tepirm-dans-levaluation-de-la-reponse-au-traitement-neoadjuvant-de
A18: =B18&"-"&C18&"-"&SUBSTITUTE(D18," ", "-") -> ID00045-ID00005-Referral | B18: ID00045 | C18: ID00005 | D18: Referral | E18: 1 | F18: https://www.aphp.fr/registre-des-essais-cliniques/tepirm-dans-levaluation-de-la-reponse-au-traitement-neoadjuvant-de
A19: =B19&"-"&C19&"-"&SUBSTITUTE(D19," ", "-") -> ID00082-ID00005-Referral | B19: ID00082 | C19: ID00005 | D19: Referral | E19: 1 | F19: https://www.aphp.fr/registre-des-essais-cliniques/tepirm-dans-levaluation-de-la-reponse-au-traitement-neoadjuvant-de
... A29: =B29&"-"&C29&"-"&SUBSTITUTE(D29," ", "-") -> ID00048-ID00047-Referral | B29: ID00048 | C29: ID00047 | D29: Referral | E29: 1 | F29: https://www.chu-clermontferrand.fr/liste-services/unite-de-bilan-et-oncologie-digestive-ubod
A30: =B30&"-"&C30&"-"&SUBSTITUTE(D30," ", "-") -> ID00048-ID00049-Referral | B30: ID00048 | C30: ID00049 | D30: Referral | E30: 1
A31: =B31&"-"&C31&"-"&SUBSTITUTE(D31," ", "-") -> ID00047-ID00049-Referral | B31: ID00047 | C31: ID00049 | D31: Referral | E31: 1
A32: =B32&"-"&C32&"-"&SUBSTITUTE(D32," ", "-") -> ID00067-ID00066-Referral | B32: ID00067 | C32: ID00066 | D32: Referral | E32: 1
A33: =B33&"-"&C33&"-"&SUBSTITUTE(D33," ", "-") -> ID00081-ID00002-Referral | B33: ID00081 | C33: ID00002 | D33: Referral | E33: 1
A34: =B34&"-"&C34&"-"&SUBSTITUTE(D34," ", "-") -> ID00081-ID00006-Referral | B34: ID00081 | C34: ID00006 | D34: Referral | E34: 1
A35: =B35&"-"&C35&"-"&SUBSTITUTE(D35," ", "-") -> ID00002-ID00081-Referral | B35: ID00002 | C35: ID00081 | D35: Referral | E35: 1
A36: =B36&"-"&C36&"-"&SUBSTITUTE(D36," ", "-") -> ID00006-ID00081-Referral | B36: ID00006 | C36: ID00081 | D36: Referral | E36: 1
A37: =B37&"-"&C37&"-"&SUBSTITUTE(D37," ", "-") -> ID00085-ID00056-Collaboration | B37: ID00085 | C37: ID00056 | D37: Collaboration | E37: 1
A38: =B38&"-"&C38&"-"&SUBSTITUTE(D38," ", "-") -> ID00056-ID00085-Collaboration | B38: ID00056 | C38: ID00085 | D38: Collaboration | E38: 1
A39: =B39&"-"&C39&"-"&SUBSTITUTE(D39," ", "-") -> ID00132-ID00085-Collaboration | B39: ID00132 | C39: ID00085 | D39: Collaboration | E39: 1 | F39: https://www.afihge.org/offre-dinstallation-a-rennes-clinique-la-sagesse/
A40: =B40&"-"&C40&"-"&SUBSTITUTE(D40," ", "-") -> ID00085-ID00132-Collaboration | B40: ID00085 | C40: ID00132 | D40: Collaboration | E40: 1 | F40: https://www.afihge.org/offre-dinstallation-a-rennes-clinique-la-sagesse/
A41: =B41&"-"&C41&"-"&SUBSTITUTE(D41," ", "-") -> ID00132-ID00056-Collaboration | B41: ID00132 | C41: ID00056 | D41: Collaboration | E41: 1 | F41: https://www.afihge.org/offre-dinstallation-a-rennes-clinique-la-sagesse/
A42: =B42&"-"&C42&"-"&SUBSTITUTE(D42," ", "-") -> ID00056-ID00132-Collaboration | B42: ID00056 | C42: ID00132 | D42: Collaboration | E42: 1 | F42: https://www.afihge.org/offre-dinstallation-a-rennes-clinique-la-sagesse/
A43: =B43&"-"&C43&"-"&SUBSTITUTE(D43," ", "-") -> ID00024-ID00079-Collaboration | B43: ID00024 | C43: ID00079 | D43: Collaboration | E43: 1
A44: =B44&"-"&C44&"-"&SUBSTITUTE(D44," ", "-") -> ID00079-ID00024-Collaboration | B44: ID00079 | C44: ID00024 | D44: Collaboration | E44: 1 | F44: https://www.chu-nice.fr/patients-visiteurs/prise-en-charge-cancer/
A45: =B45&"-"&C45&"-"&SUBSTITUTE(D45," ", "-") -> ID00025-ID00024-Surgery | B45: ID00025 | C45: ID00024 | D45: Surgery | E45: 1 | F45: https://www.chu-nice.fr/patients-visiteurs/prise-en-charge-cancer/
A46: =B46&"-"&C46&"-"&SUBSTITUTE(D46," ", "-") -> ID00069-ID00104-Surgery | B46: ID00069 | C46: ID00104 | D46: Surgery | E46: 1
A47: =B47&"-"&C47&"-"&SUBSTITUTE(D47," ", "-") -> ID00101-ID00112-Collaboration | B47: ID00101 | C47: ID00112 | D47: Collaboration | E47: 1
A48: =B48&"-"&C48&"-"&SUBSTITUTE(D48," ", "-") -> ID00112-ID00101-Collaboration | B48: ID00112 | C48: ID00101 | D48: Collaboration | E48: 1
A49: =B49&"-"&C49&"-"&SUBSTITUTE(D49," ", "-") -> ID00073-ID00145-Collaboration | B49: ID00073 | C49: ID00145 | D49: Collaboration | E49: 1
...

Sheet HCPs
B1: HCP Tier | C1: RevMeds Tiering | D1: HCP Information + Bio | J1: HCP Details | V1: HCO Details | AD1: Publications | AL1: Clinical Trials | AR1: Speaking | AS1: Associations, Key Centers/Departments
A2: Order of placement | D2: Pancreatic Cancer | E2: Pancreatic surgery | F2: PDAC OR Pancreatic Adenocarcinoma | G2: Tumour profiling/precision medicine/personalized tumor therapy | H2: Tumour board participation | I2: Role | J2: Rationale | K2: HCP_VeevaID | L2: BioLink | M2: Full name | N2: Pubmed_Name | O2: HCO Count | P2: Hospital/ Non-hospital | Q2: Head of Department | R2: Primary Specialty Group | S2: Spec 1 | T2: Spec 2 | U2: Spec 3 | V2: VeevaID | W2: GDS_HCO_ID | X2: HCO name | Y2: Address | Z2: Zipcode | AA2: Region | AB2: City | AC2: Country | AD2: No. Unique Guidelines | AE2: No. Unique Publications | AF2: KRAS AND pancreatic cancer | AG2: PDAC OR Pancreatic Adenocarcinoma | AH2: Pancreatic Cancer | AI2: Molecular Oncology (e.g. profiling) | AJ2: Personalized medicine | AK2: Next generation Sequencing | AL2: No. of Unique Clinical Trials | AM2: PDAC OR Pancreatic Adenocarcinoma | AN2: KRAS mutation | AO2: Pancreatic Cancer | AP2: Unresectable | AQ2: Metastatic | AR2: No. Speaking Events | AS2: BACAP Partner | AT2: Espoir Pancreas Patient Association | AU2: Societe Francaise Pancreas | AV2: ARCAD Foundation | AW2: Genetics and Cancer Group | AX2: FRAP (French Research Network against Pancreatic Adenocarcinoma) | AY2: French Association for Research on Pancreatic Cancer | AZ2: Pancreatic Cancer Europe | BA2: Groupe Prodige pancréas (cancer) | BB2: SOS Pancreas | BC2: PANDAURA (PDAC) Steering Committee
A3: filter | B3: filter | C3: filter | D3: filter | E3: filter | F3: filter | G3: filter | H3: filter | J3: filter | K3: filter | M3: filter | N3: filter | O3: filter | P3: filter | Q3: filter | R3: filter | S3: filter | T3: filter | U3: filter | V3: filter | W3: filter | X3: filter | Y3: filter | Z3: filter | AA3: filter | AB3: filter | AC3: filter | AD3: filter | AE3: filter | AF3: filter | AG3: filter | AH3: filter | AI3: filter | AJ3: filter | AK3: filter | AL3: filter | AM3: filter | AN3: filter | AO3: filter | AP3: filter | AQ3: filter | AR3: filter | AS3: filter | AT3: filter | AU3: filter | AV3: filter | AW3: filter | AX3: filter | AY3: filter | AZ3: filter | BA3: filter | BB3: filter | BC3: filter
B4: KOL | C4: Tier 2 | I4: Head of pancreatic cancer consultation | J4: Leads the Hepatobiliary and pancreatic surgery consultation | K4: 608464719287698474 | M4: Safi Dokmak | N4: Safi Dokmak | Q4: =IF(COUNTIFS(HCP_evidence!$A:$A, M4, HCP_evidence!$AB:$AB, "<>")>0, "Yes", "") | R4: Abdominal Surgery | S4: Abdominal Surgery | W4: ID00001 | X4: Hôpital Beaujon | AC4: France
A5: 125 | B5: KOL | C5: Tier 3 | I5: Head of department treating pancreatic cancer | J5: Member of the research committee of Societe Francaise Pancreas. Head of the Pancreatology and Digestive Oncology department. Head of the rapid pancreatic diagnostic center. | K5: 608464741240685595 | M5: Vinciane Rebours | N5: Vinciane Rebours | Q5: =IF(COUNTIFS(HCP_evidence!$A:$A, M5, HCP_evidence!$AB:$AB, "<>")>0, "Yes", "") -> Yes | R5: Gastroenterology | S5: Gastroenterology | W5: ID00001 | X5: Hôpital Beaujon | AC5: France | AU5: Yes | AW5: =IF(COUNTIFS(HCP_evidence!$A:$A, M5, HCP_evidence!$AH:$AH, "<>")>0, "Yes", "")
A6: 114 | B6: KOL | C6: Tier 2 | J6: Clinical Trial Coordinator. Member of the research committee of Societe Francaise Pancreas. Works in Pancreatology and Digestive Oncology department where pancreatic cancer is treated. Contact clinical trial | K6: 928415955849642527 | M6: Louis de Mestier | N6: Louis de Mestier | Q6: =IF(COUNTIFS(HCP_evidence!$A:$A, M6, HCP_evidence!$AB:$AB, "<>")>0, "Yes", "") | S6: Gastroenterology | T6: Gastroenterology | W6: ID00001 | X6: Hôpital Beaujon | AC6: France | AU6: Yes | AW6: =IF(COUNTIFS(HCP_evidence!$A:$A, M6, HCP_evidence!$AH:$AH, "<>")>0, "Yes", "")
J7: Works in the department of Pancreatology and Digestive Oncology specialised in pancreatic diseases. | K7: 608464692167328773 | M7: Philippe Levy | Q7: =IF(COUNTIFS(HCP_evidence!$A:$A, M7, HCP_evidence!$AB:$AB, "<>")>0, "Yes", "") | R7: Gastroenterology | S7: Gastroenterology | W7: ID00001 | X7: Hôpital Beaujon | AC7: France
J8: Works in Pancreatology and Digestive Oncology department where pancreatic cancer is treated | K8: 608464694037988405 | M8: Nelly Muller | N8: Nelly Muller | Q8: =IF(COUNTIFS(HCP_evidence!$A:$A, M8, HCP_evidence!$AB:$AB, "<>")>0, "Yes", "") | R8: Gastroenterology | S8: Gastroenterology | W8: ID00001 | X8: Hôpital Beaujon
J9: Contact person clinical trial, Accreditation coordinator of Summary Initial_managemen of pancreatic adenocarcinoma cases | K9: 608464718608221216 | M9: Alain Sauvanet | N9: Alain Sauvanet | Q9: =IF(COUNTIFS(HCP_evidence!$A:$A, M9, HCP_evidence!$AB:$AB, "<>")>0, "Yes", "") | R9: General Surgery | S9: General Surgery | T9: Surgical Oncology | W9: ID00001 | X9: Hôpital Beaujon | AC9: France | AW9: =IF(COUNTIFS(HCP_evidence!$A:$A, M9, HCP_evidence!$AH:$AH, "<>")>0, "Yes", "")
J10: Works in Pancreatology and Digestive Oncology department where pancreatic cancer is treated | K10: 626077793276412929 | M10: Olivia Hentic-Dhome | N10: Olivia Hentic | Q10: =IF(COUNTIFS(HCP_evidence!$A:$A, M10, HCP_evidence!$AB:$AB, "<>")>0, "Yes", "") | R10: Gastroenterology | S10: Gastroenterology | W10: ID00001 | X10: Hôpital Beaujon
A11: 124 | J11: Member of the research committee of Societe Francaise Pancreas. Works in Pancreatology and Digestive Oncology department where pancreatic cancer is treated | K11: 626078955694212106 | M11: Frédérique Maire | N11: Frédérique Maire | Q11: =IF(COUNTIFS(HCP_evidence!$A:$A, M11, HCP_evidence!$AB:$AB, "<>")>0, "Yes", "") | R11: Gastroenterology | S11: Gastroenterology | W11: ID00001 | X11: Hôpital Beaujon | AC11: France | AU11: Yes | AW11: =IF(COUNTIFS(HCP_evidence!$A:$A, M11, HCP_evidence!$AH:$AH, "<>")>0, "Yes", "")
J12: Works in Pancreatology and Digestive Oncology department where pancreatic cancer is treated | K12: 928864656003170847 | M12: Lucie Boyer-Laurent | Q12: =IF(COUNTIFS(HCP_evidence!$A:$A, M12, HCP_evidence!$AB:$AB, "<>")>0, "Yes", "") | R12: Gastroenterology | S12: Gastroenterology | W12: ID00001 | X12: Hôpital Beaujon
J13: Works in Pancreatology and Digestive Oncology department where pancreatic cancer is treated | K13: 929531961162596895 | M13: Caroline Lacombe | N13: Caroline Lacombe | Q13: =IF(COUNTIFS(HCP_evidence!$A:$A, M13, HCP_evidence!$AB:$AB, "<>")>0, "Yes", "") | R13: Gastroenterology | S13: Gastroenterology | W13: ID00001 | X13: Hôpital Beaujon
I14: Head of department treating pancreatic cancer | J14: Head of HPB and liver-transplant surgery where pancreatic cancer is treated | K14: 929771110830178848 | M14: Mickael Lesurtel | N14: Mickaël Lesurtel | Q14: =IF(COUNTIFS(HCP_evidence!$A:$A, M14, HCP_evidence!$AB:$AB, "<>")>0, "Yes", "") -> Yes | S14: Abdominal Surgery | T14: Abdominal Surgery | U14: Hepatobiliary Surgery | W14: ID00001 | X14: Hôpital Beaujon
A15: 52 | J15: Doctor participating in the BACAP project. Member of the research committee of Societe Francaise Pancreas. Coordinator/Director of the French Research Network against Pancreatic Adenocarcinoma. Member of the French Association for Research on Pancreatic Cancer | K15: 932572189908077919 | M15: Jérôme Cros | N15: Jérome Cros | Q15: =IF(COUNTIFS(HCP_evidence!$A:$A, M15, HCP_evidence!$AB:$AB, "<>")>0, "Yes", "") | R15: Anatomic/Clinical Pathology | S15: Anatomic/Clinical Pathology | W15: ID00001 | X15: Hôpital Beaujon | AC15: France | AS15: Yes | AU15: Yes | AW15: =IF(COUNTIFS(HCP_evidence!$A:$A, M15, HCP_evidence!$AH:$AH, "<>")>0, "Yes", "") | AX15: Yes | AY15: Yes | AZ15: Yes
J16: Works in Pancreatology and Digestive Oncology department where pancreatic cancer is treated | K16: 932692518688329062 | M16: Grégoire Salin | Q16: =IF(COUNTIFS(HCP_evidence!$A:$A, M16, HCP_evidence!$AB:$AB, "<>")>0, "Yes", "") | R16: Gastroenterology | S16: Gastroenterology | W16: ID00001 | X16: Hôpital Beaujon
J17: Works in Pancreatology and Digestive Oncology department where pancreatic cancer is treated | K17: 933656547897249144 | M17: Johanna Pokossy-Epée | N17: Johanna Pokossy Epée | Q17: =IF(COUNTIFS(HCP_evidence!$A:$A, M17, HCP_evidence!$AB:$AB, "<>")>0, "Yes", "") | R17: Gastroenterology | S17: Gastroenterology | W17: ID00001 | X17: Hôpital Beaujon
A18: 206 | J18: Works in Pancreatology and Digestive Oncology department where pancreatic cancer is treated. Principal investigator clinical trial. | K18: 934035450624806267 | M18: Anne Laure Vedie | Q18: =IF(COUNTIFS(HCP_evidence!$A:$A, M18, HCP_evidence!$AB:$AB, "<>")>0, "Yes", "") | R18: Gastroenterology | S18: Gastroenterology | W18: ID00001 | X18: Hôpital Beaujon | AC18: France | AW18: =IF(COUNTIFS(HCP_evidence!$A:$A, M18, HCP_evidence!$AH:$AH, "<>")>0, "Yes", "")
I19: Head of department treating pancreatic cancer | J19: His service performs EUS and CPRE and treats pancreatic/biliary tumours. | K19: 608464748220007427 | M19: Frédéric Prat | Q19: =IF(COUNTIFS(HCP_evidence!$A:$A, M19, HCP_evidence!$AB:$AB, "<>")>0, "Yes", "") -> Yes | W19: ID00001 | X19: Hôpital Beaujon
J20: Surgeon | K20: 626078047526732817 | L20: https://www.aphp.fr/dr-aussilhou-beatrice | M20: Béatrice Aussilhou | Q20: =IF(COUNTIFS(HCP_evidence!$A:$A, M20, HCP_evidence!$AB:$AB, "<>")>0, "Yes", "") | S20: General Surgery | W20: ID00001 | X20: Hôpital Beaujon
B21: KOL | C21: Tier 3 | J21: Head of pancreatic surgery where pancreatic cancer is treated. | K21: 621591526744540233 | M21: Philippe Bachellier | N21: Philippe Bachellier | Q21: =IF(COUNTIFS(HCP_evidence!$A:$A, M21, HCP_evidence!$AB:$AB, "<>")>0, "Yes", "") -> Yes | R21: Abdominal Surgery | S21: Abdominal Surgery | W21: ID00002 | X21: Hôpital de Hautepierre | AC21: France
J22: Head of department of HPB and liver Transplanation where pancreatic cancer surgery takes place. Principal investigator clinical trial. | K22: 626077832879031297 | M22: Pietro Addeo | N22: Pietro F Addeo | Q22: =IF(COUNTIFS(HCP_evidence!$A:$A, M22, HCP_evidence!$AB:$AB, "<>")>0, "Yes", "") -> Yes | R22: Abdominal Surgery | W22: ID00002 | X22: Hôpital de Hautepierre | AC22: France
E23: Yes | J23: Visceral and digestive surgeon where pancreatic surgery takes place. | K23: 626078475119248391 | L23: https://www.elsan.care/fr/pole-sante-sud/nos-actualites/cancer-du-pancreas-les-drs-rosso-et-amariutei-mis-lhonneur-dans-une?layout=pole-sante-sud | M23: Edoardo E Rosso | N23: Edoardo E Rosso | Q23: =IF(COUNTIFS(HCP_evidence!$A:$A, M23, HCP_evidence!$AB:$AB, "<>")>0, "Yes", "") | R23: General Surgery | S23: General Surgery | T23: Abdominal Surgery | W23: ID00003 | X23: Clinique d'Alençon | AC23: France
J24: Officially performs interventional digestive endoscopy and echo-endoscopy and has additional training in hepatobiliary tumours. | K24: 621591754444915751 | L24: https://clinique-alencon.lna-sante.com/praticiens/dr-christophe-pilette/ | M24: Christophe Pilette | Q24: =IF(COUNTIFS(HCP_evidence!$A:$A, M24, HCP_evidence!$AB:$AB, "<>")>0, "Yes", "") | W24: ID00003 | X24: Clinique d'Alençon
A25: 85 | J25: Doctor participating in the BACAP project. Reviewer of the guideline on PDAC | K25: 560999771142095885 | M25: Jean-Michel Fabre | N25: Jean-Michel Fabre | Q25: =IF(COUNTIFS(HCP_evidence!$A:$A, M25, HCP_evidence!$AB:$AB, "<>")>0, "Yes", "") | R25: Abdominal Surgery | S25: Abdominal Surgery | T25: Surgical Oncology | W25: ID00004 | X25: Hôpital Saint-Eloi | AC25: France | AS25: Yes | AW25: =IF(COUNTIFS(HCP_evidence!$A:$A, M25, HCP_evidence!$AH:$AH, "<>")>0, "Yes", "")
A26: 83 | B26: KOL | C26: Tier 2 | J26: Lead investigator in the BACAP project. Head of department treating pancreatic cancer. Contact person clinical trial. | K26: 626077447430882330 | L26: https://www.icm.unicancer.fr/fr/annuaire-professionnels/eric-assenat | M26: Eric Assénat | N26: Eric Assénat | Q26: =IF(COUNTIFS(HCP_evidence!$A:$A, M26, HCP_evidence!$AB:$AB, "<>")>0, "Yes", "") -> Yes | R26: Gastroenterology | S26: Gastroenterology | W26: ID00004 | X26: Hôpital Saint-Eloi | AC26: France | AS26: Yes | AW26: =IF(COUNTIFS(HCP_evidence!$A:$A, M26, HCP_evidence!$AH:$AH, "<>")>0, "Yes", "")
A27: 86 | J27: Doctor participating in the BACAP project. Head of Digestive, oncological and minimally invasive surgery where pancreatic cancer surgery takes place. Study director clinical trial. Reviewer of the guideline on PDAC | K27: 626079488337265677 | M27: François-Régis Souche | N27: François-Régis Souche | Q27: =IF(COUNTIFS(HCP_evidence!$A:$A, M27, HCP_evidence!$AB:$AB, "<>")>0, "Yes", "") -> Yes | R27: Abdominal Surgery | S27: Abdominal Surgery | T27: Surgical Oncology | W27: ID00004 | X27: Hôpital Saint-Eloi | AC27: France | AS27: Yes | AW27: =IF(COUNTIFS(HCP_evidence!$A:$A, M27, HCP_evidence!$AH:$AH, "<>")>0, "Yes", "")
A28: 84 | J28: Doctor participating in the BACAP project | K28: 812891185000498177 | M28: Marie Dupuy | N28: Marie Dupuy | Q28: =IF(COUNTIFS(HCP_evidence!$A:$A, M28, HCP_evidence!$AB:$AB, "<>")>0, "Yes", "") | R28: Gastroenterology | S28: Gastroenterology | T28: Medical Oncology | W28: ID00004 | X28: Hôpital Saint-Eloi | AC28: France | AS28: Yes | AW28: =IF(COUNTIFS(HCP_evidence!$A:$A, M28, HCP_evidence!$AH:$AH, "<>")>0, "Yes", "")
A29: 87 | J29: Doctor participating in the BACAP project. Part of the team of Digestive, oncological and minimally invasive surgery where pancreatic cancer surgery takes place. Contact clinical trial | K29: 934912060921744735 | M29: Thomas Bardol | N29: Thomas Bardol | Q29: =IF(COUNTIFS(HCP_evidence!$A:$A, M29, HCP_evidence!$AB:$AB, "<>")>0, "Yes", "") | R29: Abdominal Surgery | S29: Abdominal Surgery | T29: Surgical Oncology | W29: ID00004 | X29: Hôpital Saint-Eloi | AC29: France | AS29: Yes | AW29: =IF(COUNTIFS(HCP_evidence!$A:$A, M29, HCP_evidence!$AH:$AH, "<>")>0, "Yes", "")
J30: In Veeva in Italy but works in France. Performed surgery on a pancratic cancer patient. | M30: Fabrizio Panaro | N30: Fabrizio Panaro | Q30: =IF(COUNTIFS(HCP_evidence!$A:$A, M30, HCP_evidence!$AB:$AB, "<>")>0, "Yes", "") | R30: General Surgery | S30: General Surgery | T30: Surgical Oncology | W30: ID00004 | X30: Hôpital Saint-Eloi | AC30: France
J31: Head of Liver, biliary, pancreatic surgery and transplantation where pancreatic cancer surgery takes place. | K31: 626077434747307011 | M31: Francis Navarro | N31: Francis Navarro | Q31: =IF(COUNTIFS(HCP_evidence!$A:$A, M31, HCP_evidence!$AB:$AB, "<>")>0, "Yes", "") -> Yes | W31: ID00004 | X31: Hôpital Saint-Eloi
J32: Reviewer of the guideline on PDAC | K32: 626077656407884831 | M32: Jean-Christophe Valats | Q32: =IF(COUNTIFS(HCP_evidence!$A:$A, M32, HCP_evidence!$AB:$AB, "<>")>0, "Yes", "") | W32: ID00004 | X32: Hôpital Saint-Eloi
